Workbook
Name __FDS_UNIQUE_RANGE_ID_GENERATOR_COUNTER: 1740
Name _ssn2: [3]Overview!$B$20
Name _tla2: [3]Overview!$B$15
Name _tlb2: [3]Overview!$B$17
Name AbilityToPayCalc: [0]!AbilityToPayCalc
Name AmortY: [3]Ctrls!$S$23
Name BaseRate: [3]Ctrls!$L$31
Name CAGR_End: [4]Control!$C$20
Name CAGR_Start: [4]Control!$C$19
Name CapexDraw: [3]Ctrls!$L$8
Name common: [4]Control!$C$11
Name Company: [3]Ctrls!$D$8
Name Currency: [3]Ctrls!$D$13
Name data: '[4]Data Buildout'!$B$461:$BE$1141
Name Data_Col_Refs: '[4]Data Buildout'!$B$461:$B$1141
Name DATE: [4]Control!$C$12
Name DebtScen: [3]Overview!$G$5
Name DividendRule: [3]Overview!$Y$75
Name Finance: [3]Overview!$B$21
Name FRN: [3]Overview!$B$27
Name Header: [3]Ctrls!$D$11
Name HY: [3]Overview!$B$26
Name IQ_EXPENSE_CODE_: "business development"
Name kjhjklhjkl: #N/A
Name l: #N/A
Name Libor: [3]Ctrls!$T$8
Name LTM: [5]Controls!$C$24
Name ma: #N/A
Name mACROS.Info: #N/A
Name margingr: [3]Ret3!$E$15
Name mathsiadfd: #N/A
Name Mezz: [3]Overview!$B$25
Name Model: [3]Ctrls!$D$27
Name NA: "NA "
Name NM: "NM "
Name Other: [3]Overview!$B$28
Name PIK: [3]Overview!$B$30
Name PIKlife: [3]Ctrls!$L$17
Name PriceScenario: #REF!
Name Quarter: [3]Ctrls!$E$20
Name RemainYear: [3]Ctrls!$E$21
Name Run: #N/A
Name salesgr: [3]Ret3!$E$14
Name Scen: [3]Ctrls!$D$30
Name ScenName: [3]Ctrls!$E$30
Name ScenTabName: [3]Ctrls!$Q$41
Name SL: [3]Overview!$B$33
Name sName: #N/A
Name Spaces: " "
Name SSN: [3]Overview!$B$19
Name Strip_Hardcodes: #REF!
Name stub: [3]Ctrls!$D$53
Name Sweep: [3]Ctrls!$L$29
Name the_caller: #N/A
Name TLA: [3]Overview!$B$14
Name TLB: [3]Overview!$B$16
Name TLC: [3]Overview!$B$18
Name TLD: [3]Overview!$B$23
Name trdate: [3]Ctrls!$E$22
Name TrYear: [3]Ctrls!$E$19

Sheet Charts
B2: Plarium discounted cash flow analysis
B4: Revenue growth
E6: CY17A | F6: CY18A | G6: CY19F | H6: CY20F | I6: CY21F | J6: CY22F | K6: CY23F | L6: CAGR
C7: Mobile | D7: A$m | E7: =+DCF!H18 -> 158.7 | F7: =+DCF!I18 -> 208.0888 | G7: =+DCF!J18 -> 270.51544 | H7: =+DCF!K18 -> 324.61853 | I7: =+DCF!L18 -> 357.08038 | J7: =+DCF!M18 -> 392.78842 | K7: =+DCF!N18 -> 432.06726
C8: Online | D8: A$m | E8: =+DCF!H20 -> 98.7 | F8: =+DCF!I20 -> 104.80887 | G8: =+DCF!J20 -> 107.42909 | H8: =+DCF!K20 -> 110.11481 | I8: =+DCF!L20 -> 112.86769 | J8: =+DCF!M20 -> 115.68938 | K8: =+DCF!N20 -> 118.58161
C9: Label | D9: # | E9: 1 | F9: 1 | G9: 1 | H9: 1 | I9: 1 | J9: 1 | K9: 1
C10: Total | D10: A$m | E10: =SUM(E7:E8) -> 257.4 | F10: =SUM(F7:F8) -> 312.89767 | G10: =SUM(G7:G8) -> 377.94453 | H10: =SUM(H7:H8) -> 434.73334 | I10: =SUM(I7:I8) -> 469.94807 | J10: =SUM(J7:J8) -> 508.4778 | K10: =SUM(K7:K8) -> 550.64887 | L10: =(K10/G10)^(1/4)-1 -> 0.098655852
B19: Valuation summary
C21: DCF | D21: A$m | E21: 1178 | F21: 14.3
C22: Transaction / trading comps | D22: A$m | E22: 660 | F22: 11
C23: Blended valuation | D23: A$m | E23: =AVERAGE(E21:E22) -> 919 | F23: =AVERAGE(F21:F22) -> 12.65

Sheet DCF
B2: Prometheus discounted cash flow analysis
B4: Assumptions
C6: Tax Rate % | D6: % | E6: 0.32
C7: Valuation date | D7: d | E7: 43606
C8: First FY | D8: d | E8: 43830
C9: Time Share | D9: n | E9: =YEARFRAC(E7,E8) -> 0.61111111
C10: WACC | D10: % | E10: 0.09
C11: Terminal growth rate | D11: % | E11: 0.025
B13: Financials
E16: Prometheus management | J16: Citi forecasts
C17: A$m, Dec y/e | E17: 42004 | F17: =EDATE(E17,12) -> 42369 | G17: =EDATE(F17,12) -> 42735 | H17: =EDATE(G17,12) -> 43100 | I17: =EDATE(H17,12) -> 43465 | J17: =EDATE(I17,12) -> 43830 | K17: =EDATE(J17,12) -> 44196 | L17: =EDATE(K17,12) -> 44561 | M17: =EDATE(L17,12) -> 44926 | N17: =EDATE(M17,12) -> 45291
C18: Mobile net revenue | D18: A$m | E18: 8 | F18: 41.4 | G18: 97 | H18: 158.7 | I18: 208.0888 | J18: =+I18*(1+J19) -> 270.51544 | K18: =+J18*(1+K19) -> 324.61853 | L18: =+K18*(1+L19) -> 357.08038 | M18: =+L18*(1+M19) -> 392.78842 | N18: =+M18*(1+N19) -> 432.06726
C19: Growth | D19: % | F19: =+F18/E18-1 -> 4.175 | G19: =+G18/F18-1 -> 1.3429952 | H19: =+H18/G18-1 -> 0.63608247 | I19: =+I18/H18-1 -> 0.31120857 | J19: 0.3 | K19: 0.2 | L19: 0.1 | M19: =+L19 -> 0.1 | N19: =+M19 -> 0.1
C20: Online net revenue | D20: A$m | E20: 113.5 | F20: 102.3 | G20: 94.2 | H20: 98.7 | I20: 104.80887 | J20: =+I20*(1+J21) -> 107.42909 | K20: =+J20*(1+K21) -> 110.11481 | L20: =+K20*(1+L21) -> 112.86769 | M20: =+L20*(1+M21) -> 115.68938 | N20: =+M20*(1+N21) -> 118.58161
C21: Growth | D21: % | F21: =+F20/E20-1 -> -0.098678414 | G21: =+G20/F20-1 -> -0.079178886 | H21: =+H20/G20-1 -> 0.047770701 | I21: =+I20/H20-1 -> 0.061893274 | J21: 0.025 | K21: =+J21 -> 0.025 | L21: =+K21 -> 0.025 | M21: =+L21 -> 0.025 | N21: =+M21 -> 0.025
C22: Total net revenue | D22: A$m | E22: =+E18+E20 -> 121.5 | F22: =+F18+F20 -> 143.7 | G22: =+G18+G20 -> 191.2 | H22: =+H18+H20 -> 257.4 | I22: =+I18+I20 -> 312.89767 | J22: =+J18+J20 -> 377.94453 | K22: =+K18+K20 -> 434.73334 | L22: =+L18+L20 -> 469.94807 | ... N22: =+N18+N20 -> 550.64887
C23: Growth | D23: % | F23: =+F22/E22-1 -> 0.18271605 | G23: =+G22/F22-1 -> 0.33054976 | H23: =+H22/G22-1 -> 0.34623431 | I23: =+I22/H22-1 -> 0.21560865 | J23: =+J22/I22-1 -> 0.20788542 | K23: =+K22/J22-1 -> 0.15025701 | L23: =+L22/K22-1 -> 0.081003042 | M23: =+M22/L22-1 -> 0.081987209 | N23: =+N22/M22-1 -> 0.082935925
C24: Operating costs | D24: A$m | E24: =+E25-E22 -> -84.8 | F24: =+F25-F22 -> -133.9 | G24: =+G25-G22 -> -152.2 | H24: =+H25-H22 -> -196.8 | I24: =+I25-I22 -> -230.48744 | J24: =+J25-J22 -> -283.4584 | K24: =+K25-K22 -> -326.05001 | L24: =+L25-L22 -> -352.46105 | ... N24: =+N25-N22 -> -412.98666
C25: EBITDA | D25: A$m | E25: 36.7 | F25: 9.8 | G25: 39 | H25: 60.6 | I25: 82.41023 | J25: =+J26*J22 -> 94.486132 | K25: =+K26*K22 -> 108.68334 | L25: =+L26*L22 -> 117.48702 | M25: =+M26*M22 -> 127.11945 | N25: =+N26*N22 -> 137.66222
C26: Margin | D26: % | E26: =+E25/E22 -> 0.30205761 | F26: =+F25/F22 -> 0.068197634 | G26: =+G25/G22 -> 0.2039749 | H26: =+H25/H22 -> 0.23543124 | I26: =+I25/I22 -> 0.26337758 | J26: 0.25 | K26: =+J26 -> 0.25 | L26: =+K26 -> 0.25 | M26: =+L26 -> 0.25 | N26: =+M26 -> 0.25
C27: D&A | D27: A$m | E27: =+E29-E25 -> -1.3 | F27: =+F29-F25 -> -2.7 | G27: =+G29-G25 -> -4.9 | H27: =+H29-H25 -> -3.6084685 | I27: =+I29-I25 -> -3.777 | J27: =+I27*(1+$J$28) -> -3.96585 | K27: =+J27*(1+$J$28) -> -4.1641425 | L27: =+K27*(1+$J$28) -> -4.3723496 | M27: =+L27*(1+$J$28) -> -4.5909671 | N27: =+M27*(1+$J$28) -> -4.8205155
C28: Growth | D28: % | F28: =+F27/E27-1 -> 1.0769231 | G28: =+G27/F27-1 -> 0.81481481 | H28: =+H27/G27-1 -> -0.26357786 | I28: =+I27/H27-1 -> 0.04670445 | J28: 0.05 | K28: =+J28 -> 0.05 | L28: =+K28 -> 0.05 | M28: =+L28 -> 0.05 | N28: =+M28 -> 0.05
C29: EBIT | D29: A$m | E29: 35.4 | F29: 7.1 | G29: 34.1 | H29: 56.991532 | I29: 78.63323 | J29: =+J25+J27 -> 90.520282 | K29: =+K25+K27 -> 104.51919 | L29: =+L25+L27 -> 113.11467 | M29: =+M25+M27 -> 122.52848 | N29: =+N25+N27 -> 132.8417
C30: Growth | D30: % | F30: =+F29/E29-1 -> -0.79943503 | G30: =+G29/F29-1 -> 3.8028169 | H30: =+H29/G29-1 -> 0.67130591 | I30: =+I29/H29-1 -> 0.37973534 | J30: =+J29/I29-1 -> 0.15117084 | K30: =+K29/J29-1 -> 0.15464944 | L30: =+L29/K29-1 -> 0.082238232 | M30: =+M29/L29-1 -> 0.083223647 | N30: =+N29/M29-1 -> 0.084169987
C33: Cash flow items
C34: Δ NWC | D34: A$m | H34: -4.8238899 | I34: -1.3384423 | J34: =+J35*J22 -> -4.5353343 | K34: =+K35*K22 -> -5.2168001 | L34: =+L35*L22 -> -5.6393768 | M34: =+M35*M22 -> -6.1017336 | N34: =+N35*N22 -> -6.6077865
C35: % of sales | D35: % | H35: =+H34/H22 -> -0.018740831 | I35: =+I34/I22 -> -0.0042775719 | J35: -0.012 | K35: =+J35 -> -0.012 | L35: =+K35 -> -0.012 | M35: =+L35 -> -0.012 | N35: =+M35 -> -0.012
C36: Capex | D36: A$m | E36: -1.3 | F36: -2.7 | G36: -4.9 | H36: -2.9694728 | I36: -2.97 | J36: =+J27 -> -3.96585 | K36: =+K27 -> -4.1641425 | L36: =+L27 -> -4.3723496 | M36: =+M27 -> -4.5909671 | N36: =+N27 -> -4.8205155
B38: Valuation
J40: 1 | K40: =J40+1 -> 2 | L40: =K40+1 -> 3 | M40: =L40+1 -> 4 | N40: =M40+1 -> 5
C41: A$m, Dec y/e | E41: =+E17 -> 42004 | F41: =+F17 -> 42369 | G41: =+G17 -> 42735 | H41: =+H17 -> 43100 | I41: =+I17 -> 43465 | J41: =+J17 -> 43830 | K41: =+K17 -> 44196 | L41: =+L17 -> 44561 | ... N41: =+N17 -> 45291 | O41: Terminal value
C42: Revenue | D42: A$m | J42: =+J22 -> 377.94453 | K42: =+K22 -> 434.73334 | L42: =+L22 -> 469.94807 | M42: =+M22 -> 508.4778 | N42: =+N22 -> 550.64887
C43: EBITDA | D43: A$m | J43: =+J25 -> 94.486132 | K43: =+K25 -> 108.68334 | L43: =+L25 -> 117.48702 | M43: =+M25 -> 127.11945 | N43: =+N25 -> 137.66222
C44: % margin | D44: % | J44: =+J26 -> 0.25 | K44: =+K26 -> 0.25 | L44: =+L26 -> 0.25 | M44: =+M26 -> 0.25 | N44: =+N26 -> 0.25
C45: Less D&A | D45: A$m | J45: =+J27 -> -3.96585 | K45: =+K27 -> -4.1641425 | L45: =+L27 -> -4.3723496 | M45: =+M27 -> -4.5909671 | N45: =+N27 -> -4.8205155
C46: EBIT | D46: A$m | E46: =+E29 -> 35.4 | F46: =+F29 -> 7.1 | G46: =+G29 -> 34.1 | H46: =+H29 -> 56.991532 | I46: =+I29 -> 78.63323 | J46: =+J29 -> 90.520282 | K46: =+K29 -> 104.51919 | L46: =+L29 -> 113.11467 | ... N46: =+N29 -> 132.8417
C47: Less tax on EBIT | D47: A$m | E47: =+E46*$E$6*-1 -> -11.328 | F47: =+F46*$E$6*-1 -> -2.272 | G47: =+G46*$E$6*-1 -> -10.912 | H47: =+H46*$E$6*-1 -> -18.23729 | I47: =+I46*$E$6*-1 -> -25.162634 | J47: =+J46*$E$6*-1 -> -28.96649 | K47: =+K46*$E$6*-1 -> -33.446142 | L47: =+L46*$E$6*-1 -> -36.196694 | ... N47: =+N46*$E$6*-1 -> -42.509345
C48: NOPAT | D48: A$m | J48: =+J46+J47 -> 61.553792 | K48: =+K46+K47 -> 71.073052 | L48: =+L46+L47 -> 76.917974 | M48: =+M46+M47 -> 83.319368 | N48: =+N46+N47 -> 90.332358
C49: % margin | D49: % | J49: =+J48/J42 -> 0.16286462 | K49: =+K48/K42 -> 0.16348654 | L49: =+L48/L42 -> 0.16367335 | M49: =+M48/M42 -> 0.16386039 | N49: =+N48/N42 -> 0.16404711
C50: Add D&A | D50: A$m | E50: =+E27*-1 -> 1.3 | F50: =+F27*-1 -> 2.7 | G50: =+G27*-1 -> 4.9 | H50: =+H27*-1 -> 3.6084685 | I50: =+I27*-1 -> 3.777 | J50: =+J27*-1 -> 3.96585 | K50: =+K27*-1 -> 4.1641425 | L50: =+L27*-1 -> 4.3723496 | ... N50: =+N27*-1 -> 4.8205155
...
